Workbook
Name gaEff: Assumptions!$B$19
Name blockHrs: 'Pilot Pay'!$B$3
Name FedLower_Married: Assumptions!$D$11:$D$17
Name horizonAge: Assumptions!$B$8
Name useDynamic: Assumptions!$B$61
Name FedLower_Single: Assumptions!$D$2:$D$8
Name appr: Assumptions!$B$11
Name surplus_to_RE: Assumptions!$B$59
Name Sav_min: Assumptions!$B$66
Name FedUpper_Single: Assumptions!$E$2:$E$8
Name allocETF: Assumptions!$B$40
Name startAge: 'Pilot Pay'!$B$1
Name specialCatchStartAge: Assumptions!$B$38
Name startYear: 'Pilot Pay'!$B$2
Name addlMedThresh: Assumptions!$B$24
Name er401kCap_base: Assumptions!$B$29
Name mortTerm: Assumptions!$B$5
Name specialCatchEndAge: Assumptions!$B$39
Name propertiesCount: #REF!
Name total401kCap_50to59: Assumptions!$B$36
Name rentGrow: Assumptions!$B$13
Name addlMedRate: Assumptions!$B$23
Name loanTerm: Assumptions!$B$49
Name property_mgmt_fee: Assumptions!$B$56
Name taperStartAge: Assumptions!$B$68
Name ETF_min: Assumptions!$B$62
Name ETF_max: Assumptions!$B$63
Name total401kCap_60to63: Assumptions!$B$37
Name startPrice: Assumptions!$B$6
Name pctClose: Assumptions!$B$3
Name capBase: Assumptions!$B$44
Name cocYield: Assumptions!$B$12
Name lifeExcessToLoan: Assumptions!$B$46
Name allocSav: Assumptions!$B$42
Name total401kCap_u50: Assumptions!$B$35
Name FedRate_Married: Assumptions!$F$11:$F$17
Name reCashYield: Assumptions!$B$14
Name MarriageAge: Assumptions!$B$53
Name Sav_max: Assumptions!$B$67
Name pctDown: Assumptions!$B$2
Name firstPurchaseAge: Assumptions!$B$9
Name bufferPct: Assumptions!$B$15
Name loanStartAge: Assumptions!$B$50
Name rothIRA: Assumptions!$B$31
Name er401kPct: Assumptions!$B$28
Name taperEndAge: Assumptions!$B$69
Name er401kCap_catch: Assumptions!$B$30
Name cfiPay: Assumptions!$B$51
Name savGrow: Assumptions!$B$18
Name capAge: Assumptions!$B$43
Name RE_max: Assumptions!$B$65
Name FedUpper_Married: Assumptions!$E$11:$E$17
Name vacancy_rate: Assumptions!$B$55
Name lifeExcessToETF: Assumptions!$B$45
Name RE_min: Assumptions!$B$64
Name loanStartBal: Assumptions!$B$47
Name cola: 'Pilot Pay'!$B$4
Name ssRate: Assumptions!$B$20
Name retGrow: Assumptions!$B$17
Name NWSIXFIVE: Balances!$Z$2

Sheet Assumptions
A1: Assumption | B1: Value | D1: Fed Lower - Single | E1: Fed Upper - Single | F1: Fed Rate - Single
A2: Down payment percent | B2: 0.25 | D2: 0 | E2: 12400 | F2: 0.1
A3: Closing costs percent | B3: 0.03 | D3: 12401 | E3: 50400 | F3: 0.12
A4: Mortgage interest rate (fixed) | B4: 0.065 | D4: 50401 | E4: 105700 | F4: 0.22
A5: Mortgage term (years) | B5: 30 | D5: 105701 | E5: 201775 | F5: 0.24
A6: Start property price at age 24 | B6: 300000 | D6: 201776 | E6: 256225 | F6: 0.32
A7: Property price growth (inflation) | B7: 0.025 | D7: 256226 | E7: 640600 | F7: 0.35
A8: Horizon Age | B8: 65 | D8: 640601 | E8: 1000000000 | F8: 0.37
A9: First purchase age | B9: =MIN('RE Portfolio'!B2:B1015) -> 28
A10: Amortization years | B10: =horizonAge - firstPurchaseAge + 1 -> 38 | D10: Fed Lower - Married | E10: Fed Upper - Married | F10: Fed Rate - Married
A11: Appreciation (market value) | B11: 0.04 | D11: 0 | E11: 24800 | F11: 0.1
A12: Cash-on-cash yield (year 1) on down payment | B12: 0.08 | D12: 24801 | E12: 100000 | F12: 0.12
A13: Rent cash flow growth per year | B13: 0.03 | D13: 100001 | E13: 211400 | F13: 0.22
A14: RE Fund cash yield (HYSA) | B14: 0.03 | D14: 211400 | E14: 403550 | F14: 0.24
A15: Minimum RE cash buffer after purchase | B15: 0.06 | D15: 403551 | E15: 512450 | F15: 0.32
A16: ETF long-run growth | B16: 0.07 | D16: 512451 | E16: 768700 | F16: 0.35
A17: Retirement long-run growth | B17: 0.07 | D17: 768701 | E17: 1000000000 | F17: 0.37
A18: Savings/HYSA growth | B18: 0.03
A19: GA state tax effective | B19: 0.0519
A20: SS rate | B20: 0.062
A21: SS wage base | B21: 183600
A22: Medicare rate | B22: 0.0145
A23: Addl Medicare rate | B23: 0.009
A24: Addl Medicare threshold (single) | B24: 200000
A25: Employee 401k contribution | B25: 0.1
A26: Employee 401k cap (under 50) | B26: 24500
A27: Employee 401k cap (50+) | B27: 32500
A28: Employer 401k contribution | B28: 0.18
A29: Employer 401k cap (under 50) | B29: 43500
... A57: Rent-to-price ratio (initial gross yield) | B57: 0.12
A58: Savings cap ratio | B58: =9/12 -> 0.75
A59: Surplus to RE | B59: 0.5
A60: Surplus to ETF | B60: 0.5
A61: Use dynamic allocations? (TRUE/FALSE) | B61: FALSE
A62: ETF min alloc | B62: 0.2
A63: ETF max alloc | B63: 0.45
A64: RE min alloc | B64: 0.3
A65: RE max alloc | B65: 0.5
A66: Savings min alloc | B66: 0.05
A67: Savings max alloc | B67: 0.1
...

Sheet Cash Flow (Annual)
A1: Age | B1: Gross Pay | C1: Employee 401k (pre-tax) | D1: Employer 401k (benefit) | E1: Taxable Income | F1: Federal Tax | G1: GA State Tax | H1: FICA Tax | I1: Net Pay (after tax & 401k) | J1: Roth IRA (after-tax) | K1: ETF Invest (after-tax) | L1: RE Fund Contribution (after-tax) | M1: Savings (after-tax) | N1: Lifestyle Budget (pre-rent) | O1: Excess From Savings Cap | P1: Excess → ETF Invest | Q1: Excess → RE Fund | R1: Excess from Lifestyle Cap | S1: Lifestyle Cap→ETF | T1: Lifestyle Cap→Loan | U1: Loan Payment (total) | V1: RE Net Cash Flow (rent profit) | W1: Lifestyle Budget (total) | X1: Loan Payment (after-tax) | Y1: Loan Interest (accrued / paid) | Z1: Loan Principal Paid | AA1: Student Loan Balance (end of year) | AB1: Loan Balance (start of year)
A2: 18 | B2: 0 | C2: =ROUND(MIN(emp401kPct*B2, emp401kCap), 2) -> 0 | D2: =ROUND(er401kPct*B2, 2) -> 0 | E2: =MAX(0, B2 - C2) -> 0 | F2: =SUMPRODUCT( FedRate_Single, IF(E2>FedLower_Single, IF(E2<FedUpper_Single, E2, FedUpper_Single) - FedLower_Single, 0 ) ) -> 0 | G2: =ROUND(gaEff*E2, 2) -> 0 | H2: =IF(B2=0,0, ROUND( ssRate*MIN(B2, ssBase) + medRate*B2 + addlMedRate*MAX(0, B2 - addlMedThresh), 2)) -> 0 | I2: =IF(B2=0,0, ROUND(B2 - C2 - F2 - G2 - H2, 2)) -> 0 | J2: 0 | K2: =ROUND(($I2-$J2-$X2)*allocETF, 2) + IFERROR($P2, 0) -> 0 | L2: =ROUND( ($I2-$J2-$X2)*allocRE , 2) -> 0 | M2: =LET( cap_ratio, IFERROR(savings_cap_ratio, 0.75), cap_amt, cap_ratio * $W2, start_sav, IFERROR(Balances!$S2, 0), base, ROUND(($I2-$J2-$X2)*allocSav, 2), IF(start_sav >= cap_amt, 0, base) ) -> 0 | N2: =IF($A2<=capAge, MIN( ROUND( ($I2-$J2-$X2)*(1-allocETF-allocRE-allocSav), 2), capBase * (1 + inflation) ^ ($A2 - startAge) ), ROUND( ($I2-$J2-$X2)*(1-allocETF-allocRE-allocSav), 2) ) -> 0 | O2: =LET( cap_ratio, IFERROR(savings_cap_ratio, 0.75), cap_amt, cap_ratio * $W2, start_sav, IFERROR(Balances!$S2, 0), base, ROUND(($I2-$J2-$X2)*allocSav, 2), IF(start_sav >= cap_amt, base, 0) ) -> 0 | P2: =IFERROR($O2 * IFERROR(surplus_to_ETF, 0.4), 0) -> 0 | Q2: =IFERROR($O2 * IFERROR(surplus_to_RE, 0.6), 0) -> 0 | R2: =IF($A2<=capAge, MAX( 0, ROUND( ($I2-$J2-$X2)*(1-allocETF-allocRE-allocSav) - capBase * (1 + inflation) ^ ($A2 - startAge), 2) ), 0 ) -> 0 | S2: =IF(R2>0, R2*lifeExcessToETF, 0) -> 0 | T2: =IF(R2>0, R2*lifeExcessToLoan, 0) -> 0 | U2: =ROUND( MIN( X2 + IFERROR(T2,0), AB2 + Y2 ), 2 ) -> 0 | V2: {=LET( age,$A2, ti_prev,N($E1), gross,SUMIF('RE Amortization'!$E:$E,$A2,'RE Amortization'!$K:$K), fed_single,IFERROR(LOOKUP(ti_prev,N(Assumptions!$D$3:$D$9),N(Assumptions!$F$3:$F$9)),INDEX(N(Assumptions!$F$3:$F$9),1)), fed_married,IFERROR(LOOKUP(ti_prev,N(Assumptions!$D$13:$D$19),N(Assumptions!$F$13:$F$19)),INDEX(N(Assumptions!$F$13:$F$19),1)), fed_rate,IF(age<MarriageAge,fed_single,fed_married), ROUND(gross*(1-fed_rate-gaEff),2) )} -> 0 | W2: =IFERROR(N2 + V2, N2) -> 0 | X2: {=IF( AB2<=0,0, IF( A2<loanStartAge,0, MIN( AB2 + ROUND(AB2*loanRate,2), IF(A2=loanStartAge, cfiPayPct * I2, -PMT(loanRate,loanTerm,INDEX($AB:$AB,MATCH(loanStartAge,$A:$A,0))) ) ) ) )} -> 0 | Y2: =IF(AB2<=0,0,ROUND(AB2*loanRate,2)) -> 4000 | Z2: =IF(OR(AB2<=0,U2<=0),0,ROUND(MIN(AB2+Y2,U2)-Y2,2)) -> 0 | AA2: =MAX(0,ROUND(AB2 + Y2 - U2,2)) -> 84000 | AB2: =IF(A2=18, loanStartBal, OFFSET(AA2,-1,0)) -> 80000
A3: 19 | B3: 0 | C3: =ROUND(MIN(emp401kPct*B3, emp401kCap), 2) -> 0 | D3: =ROUND(er401kPct*B3, 2) -> 0 | E3: =MAX(0, B3 - C3) -> 0 | F3: =SUMPRODUCT( FedRate_Single, IF(E3>FedLower_Single, IF(E3<FedUpper_Single, E3, FedUpper_Single) - FedLower_Single, 0 ) ) -> 0 | G3: =ROUND(gaEff*E3, 2) -> 0 | H3: =IF(B3=0,0, ROUND( ssRate*MIN(B3, ssBase) + medRate*B3 + addlMedRate*MAX(0, B3 - addlMedThresh), 2)) -> 0 | I3: =IF(B3=0,0, ROUND(B3 - C3 - F3 - G3 - H3, 2)) -> 0 | J3: 0 | K3: =ROUND(($I3-$J3-$X3)*allocETF, 2) + IFERROR($P3, 0) -> 0 | L3: =ROUND( ($I3-$J3-$X3)*allocRE , 2) -> 0 | M3: =LET( cap_ratio, IFERROR(savings_cap_ratio, 0.75), cap_amt, cap_ratio * $W3, start_sav, IFERROR(Balances!$S3, 0), base, ROUND(($I3-$J3-$X3)*allocSav, 2), IF(start_sav >= cap_amt, 0, base) ) -> 0 | N3: =IF($A3<=capAge, MIN( ROUND( ($I3-$J3-$X3)*(1-allocETF-allocRE-allocSav), 2), capBase * (1 + inflation) ^ ($A3 - startAge) ), ROUND( ($I3-$J3-$X3)*(1-allocETF-allocRE-allocSav), 2) ) -> 0 | O3: =LET( cap_ratio, IFERROR(savings_cap_ratio, 0.75), cap_amt, cap_ratio * $W3, start_sav, IFERROR(Balances!$S3, 0), base, ROUND(($I3-$J3-$X3)*allocSav, 2), IF(start_sav >= cap_amt, base, 0) ) -> 0 | P3: =IFERROR($O3 * IFERROR(surplus_to_ETF, 0.4), 0) -> 0 | Q3: =IFERROR($O3 * IFERROR(surplus_to_RE, 0.6), 0) -> 0 | R3: =IF($A3<=capAge, MAX( 0, ROUND( ($I3-$J3-$X3)*(1-allocETF-allocRE-allocSav) - capBase * (1 + inflation) ^ ($A3 - startAge), 2) ), 0 ) -> 0 | S3: =IF(R3>0, R3*lifeExcessToETF, 0) -> 0 | T3: =IF(R3>0, R3*lifeExcessToLoan, 0) -> 0 | U3: =ROUND( MIN( X3 + IFERROR(T3,0), AB3 + Y3 ), 2 ) -> 0 | V3: {=LET( age,$A3, ti_prev,N($E2), gross,SUMIF('RE Amortization'!$E:$E,$A3,'RE Amortization'!$K:$K), fed_single,IFERROR(LOOKUP(ti_prev,N(Assumptions!$D$3:$D$9),N(Assumptions!$F$3:$F$9)),INDEX(N(Assumptions!$F$3:$F$9),1)), fed_married,IFERROR(LOOKUP(ti_prev,N(Assumptions!$D$13:$D$19),N(Assumptions!$F$13:$F$19)),INDEX(N(Assumptions!$F$13:$F$19),1)), fed_rate,IF(age<MarriageAge,fed_single,fed_married), ROUND(gross*(1-fed_rate-gaEff),2) )} -> 0 | W3: =IFERROR(N3 + V3, N3) -> 0 | X3: {=IF( AB3<=0,0, IF( A3<loanStartAge,0, MIN( AB3 + ROUND(AB3*loanRate,2), IF(A3=loanStartAge, cfiPayPct * I3, -PMT(loanRate,loanTerm,INDEX($AB:$AB,MATCH(loanStartAge,$A:$A,0))) ) ) ) )} -> 0 | Y3: =IF(AB3<=0,0,ROUND(AB3*loanRate,2)) -> 4200 | Z3: =IF(OR(AB3<=0,U3<=0),0,ROUND(MIN(AB3+Y3,U3)-Y3,2)) -> 0 | AA3: =MAX(0,ROUND(AB3 + Y3 - U3,2)) -> 88200 | AB3: =IF(A3=18, loanStartBal, OFFSET(AA3,-1,0)) -> 84000
A4: 20 | B4: 40000 | C4: 0 | D4: 0 | E4: =MAX(0, $B4 - $C4) -> 40000 | F4: =IFERROR( IF($A4 < MarriageAge, SUMPRODUCT( ($E4>FedLower_Single) * ((IF($E4>FedUpper_Single, FedUpper_Single, $E4))-FedLower_Single) * FedRate_Single ), SUMPRODUCT( ($E4>FedLower_Married) * ((IF($E4>FedUpper_Married, FedUpper_Married, $E4))-FedLower_Married) * FedRate_Married ) ), 0) -> 4551.88 | G4: =ROUND(gaEff*$E4, 2) -> 2076 | H4: =IF($B4=0,0, ROUND( ssRate*MIN($B4, ssBase) + medRate*$B4 + addlMedRate*MAX(0, $B4 - addlMedThresh), 2)) -> 3060 | I4: =IF($B4=0,0, ROUND($B4 - $C4 - $F4 - $G4 - $H4, 2)) -> 30312.12 | J4: 0 | K4: 0 | L4: 0 | M4: 0 | N4: =IF($A4<=capAge, MIN( ROUND( ($I4-$J4-$X4)*(1-allocETF-allocRE-allocSav), 2), capBase * (1 + inflation) ^ ($A4 - startAge) ), ROUND( ($I4-$J4-$X4)*(1-allocETF-allocRE-allocSav), 2) ) -> 0 | O4: =LET( cap_ratio, IFERROR(savings_cap_ratio, 0.75), cap_amt, cap_ratio * $W4, start_sav, IFERROR(Balances!$S4, 0), base, ROUND(($I4-$J4-$X4)*allocSav, 2), IF(start_sav >= cap_amt, base, 0) ) -> 0 | P4: =IFERROR($O4 * IFERROR(surplus_to_ETF, 0.4), 0) -> 0 | Q4: =IFERROR($O4 * IFERROR(surplus_to_RE, 0.6), 0) -> 0 | R4: =IF($A4<=capAge, MAX( 0, ROUND( ($I4-$J4-$X4)*(1-allocETF-allocRE-allocSav) - capBase * (1 + inflation) ^ ($A4 - startAge), 2) ), 0 ) -> 0 | S4: =IF(R4>0, R4*lifeExcessToETF, 0) -> 0 | T4: =IF(R4>0, R4*lifeExcessToLoan, 0) -> 0 | U4: =ROUND( MIN( X4 + IFERROR(T4,0), AB4 + Y4 ), 2 ) -> 30312.12 | V4: {=LET( age,$A4, ti_prev,N($E3), gross,SUMIF('RE Amortization'!$E:$E,$A4,'RE Amortization'!$K:$K), fed_single,IFERROR(LOOKUP(ti_prev,N(Assumptions!$D$3:$D$9),N(Assumptions!$F$3:$F$9)),INDEX(N(Assumptions!$F$3:$F$9),1)), fed_married,IFERROR(LOOKUP(ti_prev,N(Assumptions!$D$13:$D$19),N(Assumptions!$F$13:$F$19)),INDEX(N(Assumptions!$F$13:$F$19),1)), fed_rate,IF(age<MarriageAge,fed_single,fed_married), ROUND(gross*(1-fed_rate-gaEff),2) )} -> 0 | W4: =IFERROR(N4 + V4, N4) -> 0 | X4: {=IF( AB4<=0,0, IF( A4<loanStartAge,0, MIN( AB4 + ROUND(AB4*loanRate,2), IF(A4=loanStartAge, cfiPayPct * I4, -PMT(loanRate,loanTerm,INDEX($AB:$AB,MATCH(loanStartAge,$A:$A,0))) ) ) ) )} -> 30312.12 | Y4: =IF(AB4<=0,0,ROUND(AB4*loanRate,2)) -> 4410 | Z4: =IF(OR(AB4<=0,U4<=0),0,ROUND(MIN(AB4+Y4,U4)-Y4,2)) -> 25902.12 | AA4: =MAX(0,ROUND(AB4 + Y4 - U4,2)) -> 62297.88 | AB4: =IF(A4=18, loanStartBal, OFFSET(AA4,-1,0)) -> 88200
A5: 21 | B5: =IFERROR(__xludf.DUMMYFUNCTION("IFERROR( INDEX( FILTER('Pilot Pay'!R:R, VALUE('Pilot Pay'!K:K)=VALUE($A5)) , 1 ), 0 ) "),124695.53) -> 124695.53 | C5: =ROUND( MIN($B5*emp401kPct, IF($A5<catchAge, emp401kCap, emp401kCap_catch)), 2) -> 12469.55 | D5: =ROUND( MIN( MIN($B5*er401kPct, IF($A5<catchAge, er401kCap_base, er401kCap_catch)), MAX( 0, MIN($B5, IF($A5>=specialCatchStartAge, IF($A5<=specialCatchEndAge, total401kCap_60to63, total401kCap_50to59), IF($A5>=catchAge, total401kCap_50to59, total401kCap_u50) ) ) - $C5 ) ), 2) -> 22445.2 | E5: =MAX(0, $B5 - $C5) -> 112225.98 | F5: =IFERROR( IF($A5 < MarriageAge, SUMPRODUCT( ($E5>FedLower_Single) * ((IF($E5>FedUpper_Single, FedUpper_Single, $E5))-FedLower_Single) * FedRate_Single ), SUMPRODUCT( ($E5>FedLower_Married) * ((IF($E5>FedUpper_Married, FedUpper_Married, $E5))-FedLower_Married) * FedRate_Married ) ), 0) -> 19531.655 | G5: =ROUND(gaEff*$E5, 2) -> 5824.53 | H5: =IF($B5=0,0, ROUND( ssRate*MIN($B5, ssBase) + medRate*$B5 + addlMedRate*MAX(0, $B5 - addlMedThresh), 2)) -> 9539.21 | I5: =IF($B5=0,0, ROUND($B5 - $C5 - $F5 - $G5 - $H5, 2)) -> 77330.58 | J5: =ROUND( MIN(rothIRA, IF($A5<catchAge, rothCap_base, rothCap_catch)), 2) -> 7000 | K5: =ROUND(($I5-$J5-$X5)*allocETF, 2) + IFERROR($P5, 0) -> 11781.66 | L5: =ROUND( ($I5-$J5-$X5)*allocRE , 2) -> 8836.24 | M5: =LET( cap_ratio, IFERROR(savings_cap_ratio, 0.75), cap_amt, cap_ratio * $W5, start_sav, IFERROR(Balances!$S5, 0), base, ROUND(($I5-$J5-$X5)*allocSav, 2), IF(start_sav >= cap_amt, 0, base) ) -> 2945.41 | N5: =IF($A5<=capAge, MIN( ROUND( ($I5-$J5-$X5)*(1-allocETF-allocRE-allocSav), 2), capBase * (1 + inflation) ^ ($A5 - startAge) ), ROUND( ($I5-$J5-$X5)*(1-allocETF-allocRE-allocSav), 2) ) -> 16971.123 | O5: =LET( cap_ratio, IFERROR(savings_cap_ratio, 0.75), cap_amt, cap_ratio * $W5, start_sav, IFERROR(Balances!$S5, 0), base, ROUND(($I5-$J5-$X5)*allocSav, 2), IF(start_sav >= cap_amt, base, 0) ) -> 0 | P5: =IFERROR($O5 * IFERROR(surplus_to_ETF, 0.4), 0) -> 0 | Q5: =IFERROR($O5 * IFERROR(surplus_to_RE, 0.6), 0) -> 0 | R5: =IF($A5<=capAge, MAX( 0, ROUND( ($I5-$J5-$X5)*(1-allocETF-allocRE-allocSav) - capBase * (1 + inflation) ^ ($A5 - startAge), 2) ), 0 ) -> 18373.84 | S5: =IF(R5>0, R5*lifeExcessToETF, 0) -> 0 | T5: =IF(R5>0, R5*lifeExcessToLoan, 0) -> 18373.84 | U5: =ROUND( MIN( X5 + IFERROR(T5,0), AB5 + Y5 ), 2 ) -> 29796.14 | V5: {=LET( age,$A5, ti_prev,N($E4), gross,SUMIF('RE Amortization'!$E:$E,$A5,'RE Amortization'!$K:$K), fed_single,IFERROR(LOOKUP(ti_prev,N(Assumptions!$D$3:$D$9),N(Assumptions!$F$3:$F$9)),INDEX(N(Assumptions!$F$3:$F$9),1)), fed_married,IFERROR(LOOKUP(ti_prev,N(Assumptions!$D$13:$D$19),N(Assumptions!$F$13:$F$19)),INDEX(N(Assumptions!$F$13:$F$19),1)), fed_rate,IF(age<MarriageAge,fed_single,fed_married), ROUND(gross*(1-fed_rate-gaEff),2) )} -> 0 | W5: =IFERROR(N5 + V5, N5) -> 16971.123 | X5: {=IF( AB5<=0,0, IF( A5<loanStartAge,0, MIN( AB5 + ROUND(AB5*loanRate,2), IF(A5=loanStartAge, cfiPayPct * I5, -PMT(loanRate,loanTerm,INDEX($AB:$AB,MATCH(loanStartAge,$A:$A,0))) ) ) ) )} -> 11422.304 | Y5: =IF(AB5<=0,0,ROUND(AB5*loanRate,2)) -> 3114.89 | Z5: =IF(OR(AB5<=0,U5<=0),0,ROUND(MIN(AB5+Y5,U5)-Y5,2)) -> 26681.25 | AA5: =MAX(0,ROUND(AB5 + Y5 - U5,2)) -> 35616.63 | AB5: =IF(A5=18, loanStartBal, OFFSET(AA5,-1,0)) -> 62297.88
A6: 22 | B6: =IFERROR(__xludf.DUMMYFUNCTION("IFERROR( INDEX( FILTER('Pilot Pay'!R:R, VALUE('Pilot Pay'!K:K)=VALUE($A6)) , 1 ), 0 ) "),127812.92) -> 127812.92 | C6: =ROUND( MIN($B6*emp401kPct, IF($A6<catchAge, emp401kCap, emp401kCap_catch)), 2) -> 12781.29 | D6: =ROUND( MIN( MIN($B6*er401kPct, IF($A6<catchAge, er401kCap_base, er401kCap_catch)), MAX( 0, MIN($B6, IF($A6>=specialCatchStartAge, IF($A6<=specialCatchEndAge, total401kCap_60to63, total401kCap_50to59), IF($A6>=catchAge, total401kCap_50to59, total401kCap_u50) ) ) - $C6 ) ), 2) -> 23006.33 | E6: =MAX(0, $B6 - $C6) -> 115031.63 | F6: =IFERROR( IF($A6 < MarriageAge, SUMPRODUCT( ($E6>FedLower_Single) * ((IF($E6>FedUpper_Single, FedUpper_Single, $E6))-FedLower_Single) * FedRate_Single ), SUMPRODUCT( ($E6>FedLower_Married) * ((IF($E6>FedUpper_Married, FedUpper_Married, $E6))-FedLower_Married) * FedRate_Married ) ), 0) -> 20205.011 | G6: =ROUND(gaEff*$E6, 2) -> 5970.14 | H6: =IF($B6=0,0, ROUND( ssRate*MIN($B6, ssBase) + medRate*$B6 + addlMedRate*MAX(0, $B6 - addlMedThresh), 2)) -> 9777.69 | I6: =IF($B6=0,0, ROUND($B6 - $C6 - $F6 - $G6 - $H6, 2)) -> 79078.79 | J6: =ROUND( MIN(rothIRA, IF($A6<catchAge, rothCap_base, rothCap_catch)), 2) -> 7000 | K6: =ROUND(($I6-$J6-$X6)*allocETF, 2) + IFERROR($P6, 0) -> 12131.3 | L6: =ROUND( ($I6-$J6-$X6)*allocRE , 2) -> 9098.47 | M6: =LET( cap_ratio, IFERROR(savings_cap_ratio, 0.75), cap_amt, cap_ratio * $W6, start_sav, IFERROR(Balances!$S6, 0), base, ROUND(($I6-$J6-$X6)*allocSav, 2), IF(start_sav >= cap_amt, 0, base) ) -> 3032.82 | N6: =IF($A6<=capAge, MIN( ROUND( ($I6-$J6-$X6)*(1-allocETF-allocRE-allocSav), 2), capBase * (1 + inflation) ^ ($A6 - startAge) ), ROUND( ($I6-$J6-$X6)*(1-allocETF-allocRE-allocSav), 2) ) -> 17395.401 | O6: =LET( cap_ratio, IFERROR(savings_cap_ratio, 0.75), cap_amt, cap_ratio * $W6, start_sav, IFERROR(Balances!$S6, 0), base, ROUND(($I6-$J6-$X6)*allocSav, 2), IF(start_sav >= cap_amt, base, 0) ) -> 0 | P6: =IFERROR($O6 * IFERROR(surplus_to_ETF, 0.4), 0) -> 0 | Q6: =IFERROR($O6 * IFERROR(surplus_to_RE, 0.6), 0) -> 0 | R6: =IF($A6<=capAge, MAX( 0, ROUND( ($I6-$J6-$X6)*(1-allocETF-allocRE-allocSav) - capBase * (1 + inflation) ^ ($A6 - startAge), 2) ), 0 ) -> 18998.49 | S6: =IF(R6>0, R6*lifeExcessToETF, 0) -> 0 | T6: =IF(R6>0, R6*lifeExcessToLoan, 0) -> 18998.49 | U6: =ROUND( MIN( X6 + IFERROR(T6,0), AB6 + Y6 ), 2 ) -> 30420.79 | V6: {=LET( age,$A6, ti_prev,N($E5), gross,SUMIF('RE Amortization'!$E:$E,$A6,'RE Amortization'!$K:$K), fed_single,IFERROR(LOOKUP(ti_prev,N(Assumptions!$D$3:$D$9),N(Assumptions!$F$3:$F$9)),INDEX(N(Assumptions!$F$3:$F$9),1)), fed_married,IFERROR(LOOKUP(ti_prev,N(Assumptions!$D$13:$D$19),N(Assumptions!$F$13:$F$19)),INDEX(N(Assumptions!$F$13:$F$19),1)), fed_rate,IF(age<MarriageAge,fed_single,fed_married), ROUND(gross*(1-fed_rate-gaEff),2) )} -> 0 | W6: =IFERROR(N6 + V6, N6) -> 17395.401 | X6: {=IF( AB6<=0,0, IF( A6<loanStartAge,0, MIN( AB6 + ROUND(AB6*loanRate,2), IF(A6=loanStartAge, cfiPayPct * I6, -PMT(loanRate,loanTerm,INDEX($AB:$AB,MATCH(loanStartAge,$A:$A,0))) ) ) ) )} -> 11422.304 | Y6: =IF(AB6<=0,0,ROUND(AB6*loanRate,2)) -> 1780.83 | Z6: =IF(OR(AB6<=0,U6<=0),0,ROUND(MIN(AB6+Y6,U6)-Y6,2)) -> 28639.96 | AA6: =MAX(0,ROUND(AB6 + Y6 - U6,2)) -> 6976.67 | AB6: =IF(A6=18, loanStartBal, OFFSET(AA6,-1,0)) -> 35616.63
A7: 23 | B7: =IFERROR(__xludf.DUMMYFUNCTION("IFERROR( INDEX( FILTER('Pilot Pay'!R:R, VALUE('Pilot Pay'!K:K)=VALUE($A7)) , 1 ), 0 ) "),131008.25) -> 131008.25 | C7: =ROUND( MIN($B7*emp401kPct, IF($A7<catchAge, emp401kCap, emp401kCap_catch)), 2) -> 13100.83 | D7: =ROUND( MIN( MIN($B7*er401kPct, IF($A7<catchAge, er401kCap_base, er401kCap_catch)), MAX( 0, MIN($B7, IF($A7>=specialCatchStartAge, IF($A7<=specialCatchEndAge, total401kCap_60to63, total401kCap_50to59), IF($A7>=catchAge, total401kCap_50to59, total401kCap_u50) ) ) - $C7 ) ), 2) -> 23581.49 | E7: =MAX(0, $B7 - $C7) -> 117907.42 | F7: =IFERROR( IF($A7 < MarriageAge, SUMPRODUCT( ($E7>FedLower_Single) * ((IF($E7>FedUpper_Single, FedUpper_Single, $E7))-FedLower_Single) * FedRate_Single ), SUMPRODUCT( ($E7>FedLower_Married) * ((IF($E7>FedUpper_Married, FedUpper_Married, $E7))-FedLower_Married) * FedRate_Married ) ), 0) -> 20895.201 | G7: =ROUND(gaEff*$E7, 2) -> 6119.4 | H7: =IF($B7=0,0, ROUND( ssRate*MIN($B7, ssBase) + medRate*$B7 + addlMedRate*MAX(0, $B7 - addlMedThresh), 2)) -> 10022.13 | I7: =IF($B7=0,0, ROUND($B7 - $C7 - $F7 - $G7 - $H7, 2)) -> 80870.69 | J7: =ROUND( MIN(rothIRA, IF($A7<catchAge, rothCap_base, rothCap_catch)), 2) -> 7000 | K7: =ROUND(($I7-$J7-$X7)*allocETF, 2) + IFERROR($P7, 0) -> 13309.04 | L7: =ROUND( ($I7-$J7-$X7)*allocRE , 2) -> 9981.78 | M7: =LET( cap_ratio, IFERROR(savings_cap_ratio, 0.75), cap_amt, cap_ratio * $W7, start_sav, IFERROR(Balances!$S7, 0), base, ROUND(($I7-$J7-$X7)*allocSav, 2), IF(start_sav >= cap_amt, 0, base) ) -> 3327.26 | N7: =IF($A7<=capAge, MIN( ROUND( ($I7-$J7-$X7)*(1-allocETF-allocRE-allocSav), 2), capBase * (1 + inflation) ^ ($A7 - startAge) ), ROUND( ($I7-$J7-$X7)*(1-allocETF-allocRE-allocSav), 2) ) -> 39927.11 | O7: =LET( cap_ratio, IFERROR(savings_cap_ratio, 0.75), cap_amt, cap_ratio * $W7, start_sav, IFERROR(Balances!$S7, 0), base, ROUND(($I7-$J7-$X7)*allocSav, 2), IF(start_sav >= cap_amt, base, 0) ) -> 0 | P7: =IFERROR($O7 * IFERROR(surplus_to_ETF, 0.4), 0) -> 0 | Q7: =IFERROR($O7 * IFERROR(surplus_to_RE, 0.6), 0) -> 0 | R7: =IF($A7<=capAge, MAX( 0, ROUND( ($I7-$J7-$X7)*(1-allocETF-allocRE-allocSav) - capBase * (1 + inflation) ^ ($A7 - startAge), 2) ), 0 ) -> 0 | S7: =IF(R7>0, R7*lifeExcessToETF, 0) -> 0 | T7: =IF(R7>0, R7*lifeExcessToLoan, 0) -> 0 | U7: =ROUND( MIN( X7 + IFERROR(T7,0), AB7 + Y7 ), 2 ) -> 7325.5 | V7: {=LET( age,$A7, ti_prev,N($E6), gross,SUMIF('RE Amortization'!$E:$E,$A7,'RE Amortization'!$K:$K), fed_single,IFERROR(LOOKUP(ti_prev,N(Assumptions!$D$3:$D$9),N(Assumptions!$F$3:$F$9)),INDEX(N(Assumptions!$F$3:$F$9),1)), fed_married,IFERROR(LOOKUP(ti_prev,N(Assumptions!$D$13:$D$19),N(Assumptions!$F$13:$F$19)),INDEX(N(Assumptions!$F$13:$F$19),1)), fed_rate,IF(age<MarriageAge,fed_single,fed_married), ROUND(gross*(1-fed_rate-gaEff),2) )} -> 0 | W7: =IFERROR(N7 + V7, N7) -> 39927.11 | X7: {=IF( AB7<=0,0, IF( A7<loanStartAge,0, MIN( AB7 + ROUND(AB7*loanRate,2), IF(A7=loanStartAge, cfiPayPct * I7, -PMT(loanRate,loanTerm,INDEX($AB:$AB,MATCH(loanStartAge,$A:$A,0))) ) ) ) )} -> 7325.5 | Y7: =IF(AB7<=0,0,ROUND(AB7*loanRate,2)) -> 348.83 | Z7: =IF(OR(AB7<=0,U7<=0),0,ROUND(MIN(AB7+Y7,U7)-Y7,2)) -> 6976.67 | AA7: =MAX(0,ROUND(AB7 + Y7 - U7,2)) -> 0 | AB7: =IF(A7=18, loanStartBal, OFFSET(AA7,-1,0)) -> 6976.67
A8: 24 | B8: =IFERROR(__xludf.DUMMYFUNCTION("IFERROR( INDEX( FILTER('Pilot Pay'!R:R, VALUE('Pilot Pay'!K:K)=VALUE($A8)) , 1 ), 0 ) "),212487.09) -> 212487.09 | C8: =ROUND( MIN($B8*emp401kPct, IF($A8<catchAge, emp401kCap, emp401kCap_catch)), 2) -> 21248.71 | D8: =ROUND( MIN( MIN($B8*er401kPct, IF($A8<catchAge, er401kCap_base, er401kCap_catch)), MAX( 0, MIN($B8, IF($A8>=specialCatchStartAge, IF($A8<=specialCatchEndAge, total401kCap_60to63, total401kCap_50to59), IF($A8>=catchAge, total401kCap_50to59, total401kCap_u50) ) ) - $C8 ) ), 2) -> 38247.68 | E8: =MAX(0, $B8 - $C8) -> 191238.38 | F8: =IFERROR( IF($A8 < MarriageAge, SUMPRODUCT( ($E8>FedLower_Single) * ((IF($E8>FedUpper_Single, FedUpper_Single, $E8))-FedLower_Single) * FedRate_Single ), SUMPRODUCT( ($E8>FedLower_Married) * ((IF($E8>FedUpper_Married, FedUpper_Married, $E8))-FedLower_Married) * FedRate_Married ) ), 0) -> 38494.631 | G8: =ROUND(gaEff*$E8, 2) -> 9925.27 | H8: =IF($B8=0,0, ROUND( ssRate*MIN($B8, ssBase) + medRate*$B8 + addlMedRate*MAX(0, $B8 - addlMedThresh), 2)) -> 14576.65 | I8: =IF($B8=0,0, ROUND($B8 - $C8 - $F8 - $G8 - $H8, 2)) -> 128241.83 | J8: =ROUND( MIN(rothIRA, IF($A8<catchAge, rothCap_base, rothCap_catch)), 2) -> 7000 | K8: =ROUND(($I8-$J8-$X8)*allocETF, 2) + IFERROR($P8, 0) -> 24248.37 | L8: =ROUND( ($I8-$J8-$X8)*allocRE , 2) -> 18186.27 | M8: =LET( cap_ratio, IFERROR(savings_cap_ratio, 0.75), cap_amt, cap_ratio * $W8, start_sav, IFERROR(Balances!$S8, 0), base, ROUND(($I8-$J8-$X8)*allocSav, 2), IF(start_sav >= cap_amt, 0, base) ) -> 6062.09 | N8: =IF($A8<=capAge, MIN( ROUND( ($I8-$J8-$X8)*(1-allocETF-allocRE-allocSav), 2), capBase * (1 + inflation) ^ ($A8 - startAge) ), ROUND( ($I8-$J8-$X8)*(1-allocETF-allocRE-allocSav), 2) ) -> 72745.1 | O8: =LET( cap_ratio, IFERROR(savings_cap_ratio, 0.75), cap_amt, cap_ratio * $W8, start_sav, IFERROR(Balances!$S8, 0), base, ROUND(($I8-$J8-$X8)*allocSav, 2), IF(start_sav >= cap_amt, base, 0) ) -> 0 | P8: =IFERROR($O8 * IFERROR(surplus_to_ETF, 0.4), 0) -> 0 | Q8: =IFERROR($O8 * IFERROR(surplus_to_RE, 0.6), 0) -> 0 | R8: =IF($A8<=capAge, MAX( 0, ROUND( ($I8-$J8-$X8)*(1-allocETF-allocRE-allocSav) - capBase * (1 + inflation) ^ ($A8 - startAge), 2) ), 0 ) -> 0 | S8: =IF(R8>0, R8*lifeExcessToETF, 0) -> 0 | T8: =IF(R8>0, R8*lifeExcessToLoan, 0) -> 0 | U8: =ROUND( MIN( X8 + IFERROR(T8,0), AB8 + Y8 ), 2 ) -> 0 | V8: {=LET( age,$A8, ti_prev,N($E7), gross,SUMIF('RE Amortization'!$E:$E,$A8,'RE Amortization'!$K:$K), fed_single,IFERROR(LOOKUP(ti_prev,N(Assumptions!$D$3:$D$9),N(Assumptions!$F$3:$F$9)),INDEX(N(Assumptions!$F$3:$F$9),1)), fed_married,IFERROR(LOOKUP(ti_prev,N(Assumptions!$D$13:$D$19),N(Assumptions!$F$13:$F$19)),INDEX(N(Assumptions!$F$13:$F$19),1)), fed_rate,IF(age<MarriageAge,fed_single,fed_married), ROUND(gross*(1-fed_rate-gaEff),2) )} -> 0 | W8: =IFERROR(N8 + V8, N8) -> 72745.1 | X8: {=IF( AB8<=0,0, IF( A8<loanStartAge,0, MIN( AB8 + ROUND(AB8*loanRate,2), IF(A8=loanStartAge, cfiPayPct * I8, -PMT(loanRate,loanTerm,INDEX($AB:$AB,MATCH(loanStartAge,$A:$A,0))) ) ) ) )} -> 0 | Y8: =IF(AB8<=0,0,ROUND(AB8*loanRate,2)) -> 0 | Z8: =IF(OR(AB8<=0,U8<=0),0,ROUND(MIN(AB8+Y8,U8)-Y8,2)) -> 0 | AA8: =MAX(0,ROUND(AB8 + Y8 - U8,2)) -> 0 | AB8: =IF(A8=18, loanStartBal, OFFSET(AA8,-1,0)) -> 0
A9: 25 | B9: =IFERROR(__xludf.DUMMYFUNCTION("IFERROR( INDEX( FILTER('Pilot Pay'!R:R, VALUE('Pilot Pay'!K:K)=VALUE($A9)) , 1 ), 0 ) "),247669.63) -> 247669.63 | C9: =ROUND( MIN($B9*emp401kPct, IF($A9<catchAge, emp401kCap, emp401kCap_catch)), 2) -> 24500 | D9: =ROUND( MIN( MIN($B9*er401kPct, IF($A9<catchAge, er401kCap_base, er401kCap_catch)), MAX( 0, MIN($B9, IF($A9>=specialCatchStartAge, IF($A9<=specialCatchEndAge, total401kCap_60to63, total401kCap_50to59), IF($A9>=catchAge, total401kCap_50to59, total401kCap_u50) ) ) - $C9 ) ), 2) -> 43500 | E9: =MAX(0, $B9 - $C9) -> 223169.63 | F9: =IFERROR( IF($A9 < MarriageAge, SUMPRODUCT( ($E9>FedLower_Single) * ((IF($E9>FedUpper_Single, FedUpper_Single, $E9))-FedLower_Single) * FedRate_Single ), SUMPRODUCT( ($E9>FedLower_Married) * ((IF($E9>FedUpper_Married, FedUpper_Married, $E9))-FedLower_Married) * FedRate_Married ) ), 0) -> 47869.382 | G9: =ROUND(gaEff*$E9, 2) -> 11582.5 | H9: =IF($B9=0,0, ROUND( ssRate*MIN($B9, ssBase) + medRate*$B9 + addlMedRate*MAX(0, $B9 - addlMedThresh), 2)) -> 15403.44 | I9: =IF($B9=0,0, ROUND($B9 - $C9 - $F9 - $G9 - $H9, 2)) -> 148314.31 | J9: =ROUND( MIN(rothIRA, IF($A9<catchAge, rothCap_base, rothCap_catch)), 2) -> 7000 | K9: =ROUND(($I9-$J9-$X9)*allocETF, 2) + IFERROR($P9, 0) -> 28262.86 | L9: =ROUND( ($I9-$J9-$X9)*allocRE , 2) -> 21197.15 | M9: =LET( cap_ratio, IFERROR(savings_cap_ratio, 0.75), cap_amt, cap_ratio * $W9, start_sav, IFERROR(Balances!$S9, 0), base, ROUND(($I9-$J9-$X9)*allocSav, 2), IF(start_sav >= cap_amt, 0, base) ) -> 7065.72 | N9: =IF($A9<=capAge, MIN( ROUND( ($I9-$J9-$X9)*(1-allocETF-allocRE-allocSav), 2), capBase * (1 + inflation) ^ ($A9 - startAge) ), ROUND( ($I9-$J9-$X9)*(1-allocETF-allocRE-allocSav), 2) ) -> 84788.59 | O9: =LET( cap_ratio, IFERROR(savings_cap_ratio, 0.75), cap_amt, cap_ratio * $W9, start_sav, IFERROR(Balances!$S9, 0), base, ROUND(($I9-$J9-$X9)*allocSav, 2), IF(start_sav >= cap_amt, base, 0) ) -> 0 | P9: =IFERROR($O9 * IFERROR(surplus_to_ETF, 0.4), 0) -> 0 | Q9: =IFERROR($O9 * IFERROR(surplus_to_RE, 0.6), 0) -> 0 | R9: =IF($A9<=capAge, MAX( 0, ROUND( ($I9-$J9-$X9)*(1-allocETF-allocRE-allocSav) - capBase * (1 + inflation) ^ ($A9 - startAge), 2) ), 0 ) -> 0 | S9: =IF(R9>0, R9*lifeExcessToETF, 0) -> 0 | T9: =IF(R9>0, R9*lifeExcessToLoan, 0) -> 0 | U9: =ROUND( MIN( X9 + IFERROR(T9,0), AB9 + Y9 ), 2 ) -> 0 | V9: {=LET( age,$A9, ti_prev,N($E8), gross,SUMIF('RE Amortization'!$E:$E,$A9,'RE Amortization'!$K:$K), fed_single,IFERROR(LOOKUP(ti_prev,N(Assumptions!$D$3:$D$9),N(Assumptions!$F$3:$F$9)),INDEX(N(Assumptions!$F$3:$F$9),1)), fed_married,IFERROR(LOOKUP(ti_prev,N(Assumptions!$D$13:$D$19),N(Assumptions!$F$13:$F$19)),INDEX(N(Assumptions!$F$13:$F$19),1)), fed_rate,IF(age<MarriageAge,fed_single,fed_married), ROUND(gross*(1-fed_rate-gaEff),2) )} -> 0 | W9: =IFERROR(N9 + V9, N9) -> 84788.59 | X9: {=IF( AB9<=0,0, IF( A9<loanStartAge,0, MIN( AB9 + ROUND(AB9*loanRate,2), IF(A9=loanStartAge, cfiPayPct * I9, -PMT(loanRate,loanTerm,INDEX($AB:$AB,MATCH(loanStartAge,$A:$A,0))) ) ) ) )} -> 0 | Y9: =IF(AB9<=0,0,ROUND(AB9*loanRate,2)) -> 0 | Z9: =IF(OR(AB9<=0,U9<=0),0,ROUND(MIN(AB9+Y9,U9)-Y9,2)) -> 0 | AA9: =MAX(0,ROUND(AB9 + Y9 - U9,2)) -> 0 | AB9: =IF(A9=18, loanStartBal, OFFSET(AA9,-1,0)) -> 0
A10: 26 | B10: =IFERROR(__xludf.DUMMYFUNCTION("IFERROR( INDEX( FILTER('Pilot Pay'!R:R, VALUE('Pilot Pay'!K:K)=VALUE($A10)) , 1 ), 0 ) "),403485.15) -> 403485.15 | C10: =ROUND( MIN($B10*emp401kPct, IF($A10<catchAge, emp401kCap, emp401kCap_catch)), 2) -> 24500 | D10: =ROUND( MIN( MIN($B10*er401kPct, IF($A10<catchAge, er401kCap_base, er401kCap_catch)), MAX( 0, MIN($B10, IF($A10>=specialCatchStartAge, IF($A10<=specialCatchEndAge, total401kCap_60to63, total401kCap_50to59), IF($A10>=catchAge, total401kCap_50to59, total401kCap_u50) ) ) - $C10 ) ), 2) -> 43500 | E10: =MAX(0, $B10 - $C10) -> 378985.15 | F10: =IFERROR( IF($A10 < MarriageAge, SUMPRODUCT( ($E10>FedLower_Single) * ((IF($E10>FedUpper_Single, FedUpper_Single, $E10))-FedLower_Single) * FedRate_Single ), SUMPRODUCT( ($E10>FedLower_Married) * ((IF($E10>FedUpper_Married, FedUpper_Married, $E10))-FedLower_Married) * FedRate_Married ) ), 0) -> 101412.8 | G10: =ROUND(gaEff*$E10, 2) -> 19669.33 | H10: =IF($B10=0,0, ROUND( ssRate*MIN($B10, ssBase) + medRate*$B10 + addlMedRate*MAX(0, $B10 - addlMedThresh), 2)) -> 19065.1 | I10: =IF($B10=0,0, ROUND($B10 - $C10 - $F10 - $G10 - $H10, 2)) -> 238837.92 | J10: =ROUND( MIN(rothIRA, IF($A10<catchAge, rothCap_base, rothCap_catch)), 2) -> 7000 | K10: =ROUND(($I10-$J10-$X10)*allocETF, 2) + IFERROR($P10, 0) -> 46367.58 | L10: =ROUND( ($I10-$J10-$X10)*allocRE , 2) -> 34775.69 | M10: =LET( cap_ratio, IFERROR(savings_cap_ratio, 0.75), cap_amt, cap_ratio * $W10, start_sav, IFERROR(Balances!$S10, 0), base, ROUND(($I10-$J10-$X10)*allocSav, 2), IF(start_sav >= cap_amt, 0, base) ) -> 11591.9 | N10: =IF($A10<=capAge, MIN( ROUND( ($I10-$J10-$X10)*(1-allocETF-allocRE-allocSav), 2), capBase * (1 + inflation) ^ ($A10 - startAge) ), ROUND( ($I10-$J10-$X10)*(1-allocETF-allocRE-allocSav), 2) ) -> 139102.75 | O10: =LET( cap_ratio, IFERROR(savings_cap_ratio, 0.75), cap_amt, cap_ratio * $W10, start_sav, IFERROR(Balances!$S10, 0), base, ROUND(($I10-$J10-$X10)*allocSav, 2), IF(start_sav >= cap_amt, base, 0) ) -> 0 | P10: =IFERROR($O10 * IFERROR(surplus_to_ETF, 0.4), 0) -> 0 | Q10: =IFERROR($O10 * IFERROR(surplus_to_RE, 0.6), 0) -> 0 | R10: =IF($A10<=capAge, MAX( 0, ROUND( ($I10-$J10-$X10)*(1-allocETF-allocRE-allocSav) - capBase * (1 + inflation) ^ ($A10 - startAge), 2) ), 0 ) -> 0 | S10: =IF(R10>0, R10*lifeExcessToETF, 0) -> 0 | T10: =IF(R10>0, R10*lifeExcessToLoan, 0) -> 0 | U10: =ROUND( MIN( X10 + IFERROR(T10,0), AB10 + Y10 ), 2 ) -> 0 | V10: {=LET( age,$A10, ti_prev,N($E9), gross,SUMIF('RE Amortization'!$E:$E,$A10,'RE Amortization'!$K:$K), fed_single,IFERROR(LOOKUP(ti_prev,N(Assumptions!$D$3:$D$9),N(Assumptions!$F$3:$F$9)),INDEX(N(Assumptions!$F$3:$F$9),1)), fed_married,IFERROR(LOOKUP(ti_prev,N(Assumptions!$D$13:$D$19),N(Assumptions!$F$13:$F$19)),INDEX(N(Assumptions!$F$13:$F$19),1)), fed_rate,IF(age<MarriageAge,fed_single,fed_married), ROUND(gross*(1-fed_rate-gaEff),2) )} -> 0 | W10: =IFERROR(N10 + V10, N10) -> 139102.75 | X10: {=IF( AB10<=0,0, IF( A10<loanStartAge,0, MIN( AB10 + ROUND(AB10*loanRate,2), IF(A10=loanStartAge, cfiPayPct * I10, -PMT(loanRate,loanTerm,INDEX($AB:$AB,MATCH(loanStartAge,$A:$A,0))) ) ) ) )} -> 0 | Y10: =IF(AB10<=0,0,ROUND(AB10*loanRate,2)) -> 0 | Z10: =IF(OR(AB10<=0,U10<=0),0,ROUND(MIN(AB10+Y10,U10)-Y10,2)) -> 0 | AA10: =MAX(0,ROUND(AB10 + Y10 - U10,2)) -> 0 | AB10: =IF(A10=18, loanStartBal, OFFSET(AA10,-1,0)) -> 0
A11: 27 | B11: =IFERROR(__xludf.DUMMYFUNCTION("IFERROR( INDEX( FILTER('Pilot Pay'!R:R, VALUE('Pilot Pay'!K:K)=VALUE($A11)) , 1 ), 0 ) "),421763.54) -> 421763.54 | C11: =ROUND( MIN($B11*emp401kPct, IF($A11<catchAge, emp401kCap, emp401kCap_catch)), 2) -> 24500 | D11: =ROUND( MIN( MIN($B11*er401kPct, IF($A11<catchAge, er401kCap_base, er401kCap_catch)), MAX( 0, MIN($B11, IF($A11>=specialCatchStartAge, IF($A11<=specialCatchEndAge, total401kCap_60to63, total401kCap_50to59), IF($A11>=catchAge, total401kCap_50to59, total401kCap_u50) ) ) - $C11 ) ), 2) -> 43500 | E11: =MAX(0, $B11 - $C11) -> 397263.54 | F11: =IFERROR( IF($A11 < MarriageAge, SUMPRODUCT( ($E11>FedLower_Single) * ((IF($E11>FedUpper_Single, FedUpper_Single, $E11))-FedLower_Single) * FedRate_Single ), SUMPRODUCT( ($E11>FedLower_Married) * ((IF($E11>FedUpper_Married, FedUpper_Married, $E11))-FedLower_Married) * FedRate_Married ) ), 0) -> 107810.24 | G11: =ROUND(gaEff*$E11, 2) -> 20617.98 | H11: =IF($B11=0,0, ROUND( ssRate*MIN($B11, ssBase) + medRate*$B11 + addlMedRate*MAX(0, $B11 - addlMedThresh), 2)) -> 19494.64 | I11: =IF($B11=0,0, ROUND($B11 - $C11 - $F11 - $G11 - $H11, 2)) -> 249340.68 | J11: =ROUND( MIN(rothIRA, IF($A11<catchAge, rothCap_base, rothCap_catch)), 2) -> 7000 | K11: =ROUND(($I11-$J11-$X11)*allocETF, 2) + IFERROR($P11, 0) -> 48468.14 | L11: =ROUND( ($I11-$J11-$X11)*allocRE , 2) -> 36351.1 | M11: =LET( cap_ratio, IFERROR(savings_cap_ratio, 0.75), cap_amt, cap_ratio * $W11, start_sav, IFERROR(Balances!$S11, 0), base, ROUND(($I11-$J11-$X11)*allocSav, 2), IF(start_sav >= cap_amt, 0, base) ) -> 12117.03 | N11: =IF($A11<=capAge, MIN( ROUND( ($I11-$J11-$X11)*(1-allocETF-allocRE-allocSav), 2), capBase * (1 + inflation) ^ ($A11 - startAge) ), ROUND( ($I11-$J11-$X11)*(1-allocETF-allocRE-allocSav), 2) ) -> 145404.41 | O11: =LET( cap_ratio, IFERROR(savings_cap_ratio, 0.75), cap_amt, cap_ratio * $W11, start_sav, IFERROR(Balances!$S11, 0), base, ROUND(($I11-$J11-$X11)*allocSav, 2), IF(start_sav >= cap_amt, base, 0) ) -> 0 | P11: =IFERROR($O11 * IFERROR(surplus_to_ETF, 0.4), 0) -> 0 | Q11: =IFERROR($O11 * IFERROR(surplus_to_RE, 0.6), 0) -> 0 | R11: =IF($A11<=capAge, MAX( 0, ROUND( ($I11-$J11-$X11)*(1-allocETF-allocRE-allocSav) - capBase * (1 + inflation) ^ ($A11 - startAge), 2) ), 0 ) -> 0 | S11: =IF(R11>0, R11*lifeExcessToETF, 0) -> 0 | T11: =IF(R11>0, R11*lifeExcessToLoan, 0) -> 0 | U11: =ROUND( MIN( X11 + IFERROR(T11,0), AB11 + Y11 ), 2 ) -> 0 | V11: {=LET( age,$A11, ti_prev,N($E10), gross,SUMIF('RE Amortization'!$E:$E,$A11,'RE Amortization'!$K:$K), fed_single,IFERROR(LOOKUP(ti_prev,N(Assumptions!$D$3:$D$9),N(Assumptions!$F$3:$F$9)),INDEX(N(Assumptions!$F$3:$F$9),1)), fed_married,IFERROR(LOOKUP(ti_prev,N(Assumptions!$D$13:$D$19),N(Assumptions!$F$13:$F$19)),INDEX(N(Assumptions!$F$13:$F$19),1)), fed_rate,IF(age<MarriageAge,fed_single,fed_married), ROUND(gross*(1-fed_rate-gaEff),2) )} -> 0 | W11: =IFERROR(N11 + V11, N11) -> 145404.41 | X11: {=IF( AB11<=0,0, IF( A11<loanStartAge,0, MIN( AB11 + ROUND(AB11*loanRate,2), IF(A11=loanStartAge, cfiPayPct * I11, -PMT(loanRate,loanTerm,INDEX($AB:$AB,MATCH(loanStartAge,$A:$A,0))) ) ) ) )} -> 0 | Y11: =IF(AB11<=0,0,ROUND(AB11*loanRate,2)) -> 0 | Z11: =IF(OR(AB11<=0,U11<=0),0,ROUND(MIN(AB11+Y11,U11)-Y11,2)) -> 0 | AA11: =MAX(0,ROUND(AB11 + Y11 - U11,2)) -> 0 | AB11: =IF(A11=18, loanStartBal, OFFSET(AA11,-1,0)) -> 0
A12: 28 | B12: =IFERROR(__xludf.DUMMYFUNCTION("IFERROR( INDEX( FILTER('Pilot Pay'!R:R, VALUE('Pilot Pay'!K:K)=VALUE($A12)) , 1 ), 0 ) "),439947.9) -> 439947.9 | C12: =ROUND( MIN($B12*emp401kPct, IF($A12<catchAge, emp401kCap, emp401kCap_catch)), 2) -> 24500 | D12: =ROUND( MIN( MIN($B12*er401kPct, IF($A12<catchAge, er401kCap_base, er401kCap_catch)), MAX( 0, MIN($B12, IF($A12>=specialCatchStartAge, IF($A12<=specialCatchEndAge, total401kCap_60to63, total401kCap_50to59), IF($A12>=catchAge, total401kCap_50to59, total401kCap_u50) ) ) - $C12 ) ), 2) -> 43500 | E12: =MAX(0, $B12 - $C12) -> 415447.9 | F12: =IFERROR( IF($A12 < MarriageAge, SUMPRODUCT( ($E12>FedLower_Single) * ((IF($E12>FedUpper_Single, FedUpper_Single, $E12))-FedLower_Single) * FedRate_Single ), SUMPRODUCT( ($E12>FedLower_Married) * ((IF($E12>FedUpper_Married, FedUpper_Married, $E12))-FedLower_Married) * FedRate_Married ) ), 0) -> 114174.76 | G12: =ROUND(gaEff*$E12, 2) -> 21561.75 | H12: =IF($B12=0,0, ROUND( ssRate*MIN($B12, ssBase) + medRate*$B12 + addlMedRate*MAX(0, $B12 - addlMedThresh), 2)) -> 19921.98 | I12: =IF($B12=0,0, ROUND($B12 - $C12 - $F12 - $G12 - $H12, 2)) -> 259789.41 | J12: =ROUND( MIN(rothIRA, IF($A12<catchAge, rothCap_base, rothCap_catch)), 2) -> 7000 | K12: =ROUND(($I12-$J12-$X12)*allocETF, 2) + IFERROR($P12, 0) -> 50557.88 | L12: =ROUND( ($I12-$J12-$X12)*allocRE , 2) -> 37918.41 | M12: =LET( cap_ratio, IFERROR(savings_cap_ratio, 0.75), cap_amt, cap_ratio * $W12, start_sav, IFERROR(Balances!$S12, 0), base, ROUND(($I12-$J12-$X12)*allocSav, 2), IF(start_sav >= cap_amt, 0, base) ) -> 12639.47 | N12: =IF($A12<=capAge, MIN( ROUND( ($I12-$J12-$X12)*(1-allocETF-allocRE-allocSav), 2), capBase * (1 + inflation) ^ ($A12 - startAge) ), ROUND( ($I12-$J12-$X12)*(1-allocETF-allocRE-allocSav), 2) ) -> 151673.65 | O12: =LET( cap_ratio, IFERROR(savings_cap_ratio, 0.75), cap_amt, cap_ratio * $W12, start_sav, IFERROR(Balances!$S12, 0), base, ROUND(($I12-$J12-$X12)*allocSav, 2), IF(start_sav >= cap_amt, base, 0) ) -> 0 | P12: =IFERROR($O12 * IFERROR(surplus_to_ETF, 0.4), 0) -> 0 | Q12: =IFERROR($O12 * IFERROR(surplus_to_RE, 0.6), 0) -> 0 | R12: =IF($A12<=capAge, MAX( 0, ROUND( ($I12-$J12-$X12)*(1-allocETF-allocRE-allocSav) - capBase * (1 + inflation) ^ ($A12 - startAge), 2) ), 0 ) -> 0 | S12: =IF(R12>0, R12*lifeExcessToETF, 0) -> 0 | T12: =IF(R12>0, R12*lifeExcessToLoan, 0) -> 0 | U12: =ROUND( MIN( X12 + IFERROR(T12,0), AB12 + Y12 ), 2 ) -> 0 | V12: {=LET( age,$A12, ti_prev,N($E11), gross,SUMIF('RE Amortization'!$E:$E,$A12,'RE Amortization'!$K:$K), fed_single,IFERROR(LOOKUP(ti_prev,N(Assumptions!$D$3:$D$9),N(Assumptions!$F$3:$F$9)),INDEX(N(Assumptions!$F$3:$F$9),1)), fed_married,IFERROR(LOOKUP(ti_prev,N(Assumptions!$D$13:$D$19),N(Assumptions!$F$13:$F$19)),INDEX(N(Assumptions!$F$13:$F$19),1)), fed_rate,IF(age<MarriageAge,fed_single,fed_married), ROUND(gross*(1-fed_rate-gaEff),2) )} -> 4802.66 | W12: =IFERROR(N12 + V12, N12) -> 156476.31 | X12: {=IF( AB12<=0,0, IF( A12<loanStartAge,0, MIN( AB12 + ROUND(AB12*loanRate,2), IF(A12=loanStartAge, cfiPayPct * I12, -PMT(loanRate,loanTerm,INDEX($AB:$AB,MATCH(loanStartAge,$A:$A,0))) ) ) ) )} -> 0 | Y12: =IF(AB12<=0,0,ROUND(AB12*loanRate,2)) -> 0 | Z12: =IF(OR(AB12<=0,U12<=0),0,ROUND(MIN(AB12+Y12,U12)-Y12,2)) -> 0 | AA12: =MAX(0,ROUND(AB12 + Y12 - U12,2)) -> 0 | AB12: =IF(A12=18, loanStartBal, OFFSET(AA12,-1,0)) -> 0
A13: 29 | B13: =IFERROR(__xludf.DUMMYFUNCTION("IFERROR( INDEX( FILTER('Pilot Pay'!R:R, VALUE('Pilot Pay'!K:K)=VALUE($A13)) , 1 ), 0 ) "),537236.01) -> 537236.01 | C13: =ROUND( MIN($B13*emp401kPct, IF($A13<catchAge, emp401kCap, emp401kCap_catch)), 2) -> 24500 | D13: =ROUND( MIN( MIN($B13*er401kPct, IF($A13<catchAge, er401kCap_base, er401kCap_catch)), MAX( 0, MIN($B13, IF($A13>=specialCatchStartAge, IF($A13<=specialCatchEndAge, total401kCap_60to63, total401kCap_50to59), IF($A13>=catchAge, total401kCap_50to59, total401kCap_u50) ) ) - $C13 ) ), 2) -> 43500 | E13: =MAX(0, $B13 - $C13) -> 512736.01 | F13: =IFERROR( IF($A13 < MarriageAge, SUMPRODUCT( ($E13>FedLower_Single) * ((IF($E13>FedUpper_Single, FedUpper_Single, $E13))-FedLower_Single) * FedRate_Single ), SUMPRODUCT( ($E13>FedLower_Married) * ((IF($E13>FedUpper_Married, FedUpper_Married, $E13))-FedLower_Married) * FedRate_Married ) ), 0) -> 148225.6 | G13: =ROUND(gaEff*$E13, 2) -> 26611 | H13: =IF($B13=0,0, ROUND( ssRate*MIN($B13, ssBase) + medRate*$B13 + addlMedRate*MAX(0, $B13 - addlMedThresh), 2)) -> 22208.25 | I13: =IF($B13=0,0, ROUND($B13 - $C13 - $F13 - $G13 - $H13, 2)) -> 315691.16 | J13: =ROUND( MIN(rothIRA, IF($A13<catchAge, rothCap_base, rothCap_catch)), 2) -> 7000 | K13: =ROUND(($I13-$J13-$X13)*allocETF, 2) + IFERROR($P13, 0) -> 61738.23 | L13: =ROUND( ($I13-$J13-$X13)*allocRE , 2) -> 46303.67 | M13: =LET( cap_ratio, IFERROR(savings_cap_ratio, 0.75), cap_amt, cap_ratio * $W13, start_sav, IFERROR(Balances!$S13, 0), base, ROUND(($I13-$J13-$X13)*allocSav, 2), IF(start_sav >= cap_amt, 0, base) ) -> 15434.56 | N13: =IF($A13<=capAge, MIN( ROUND( ($I13-$J13-$X13)*(1-allocETF-allocRE-allocSav), 2), capBase * (1 + inflation) ^ ($A13 - startAge) ), ROUND( ($I13-$J13-$X13)*(1-allocETF-allocRE-allocSav), 2) ) -> 185214.7 | O13: =LET( cap_ratio, IFERROR(savings_cap_ratio, 0.75), cap_amt, cap_ratio * $W13, start_sav, IFERROR(Balances!$S13, 0), base, ROUND(($I13-$J13-$X13)*allocSav, 2), IF(start_sav >= cap_amt, base, 0) ) -> 0 | P13: =IFERROR($O13 * IFERROR(surplus_to_ETF, 0.4), 0) -> 0 | Q13: =IFERROR($O13 * IFERROR(surplus_to_RE, 0.6), 0) -> 0 | R13: =IF($A13<=capAge, MAX( 0, ROUND( ($I13-$J13-$X13)*(1-allocETF-allocRE-allocSav) - capBase * (1 + inflation) ^ ($A13 - startAge), 2) ), 0 ) -> 0 | S13: =IF(R13>0, R13*lifeExcessToETF, 0) -> 0 | T13: =IF(R13>0, R13*lifeExcessToLoan, 0) -> 0 | U13: =ROUND( MIN( X13 + IFERROR(T13,0), AB13 + Y13 ), 2 ) -> 0 | V13: {=LET( age,$A13, ti_prev,N($E12), gross,SUMIF('RE Amortization'!$E:$E,$A13,'RE Amortization'!$K:$K), fed_single,IFERROR(LOOKUP(ti_prev,N(Assumptions!$D$3:$D$9),N(Assumptions!$F$3:$F$9)),INDEX(N(Assumptions!$F$3:$F$9),1)), fed_married,IFERROR(LOOKUP(ti_prev,N(Assumptions!$D$13:$D$19),N(Assumptions!$F$13:$F$19)),INDEX(N(Assumptions!$F$13:$F$19),1)), fed_rate,IF(age<MarriageAge,fed_single,fed_married), ROUND(gross*(1-fed_rate-gaEff),2) )} -> 4802.66 | W13: =IFERROR(N13 + V13, N13) -> 190017.36 | X13: {=IF( AB13<=0,0, IF( A13<loanStartAge,0, MIN( AB13 + ROUND(AB13*loanRate,2), IF(A13=loanStartAge, cfiPayPct * I13, -PMT(loanRate,loanTerm,INDEX($AB:$AB,MATCH(loanStartAge,$A:$A,0))) ) ) ) )} -> 0 | Y13: =IF(AB13<=0,0,ROUND(AB13*loanRate,2)) -> 0 | Z13: =IF(OR(AB13<=0,U13<=0),0,ROUND(MIN(AB13+Y13,U13)-Y13,2)) -> 0 | AA13: =MAX(0,ROUND(AB13 + Y13 - U13,2)) -> 0 | AB13: =IF(A13=18, loanStartBal, OFFSET(AA13,-1,0)) -> 0
A14: 30 | B14: =IFERROR(__xludf.DUMMYFUNCTION("IFERROR( INDEX( FILTER('Pilot Pay'!R:R, VALUE('Pilot Pay'!K:K)=VALUE($A14)) , 1 ), 0 ) "),555133.29) -> 555133.29 | C14: =ROUND( MIN($B14*emp401kPct, IF($A14<catchAge, emp401kCap, emp401kCap_catch)), 2) -> 24500 | D14: =ROUND( MIN( MIN($B14*er401kPct, IF($A14<catchAge, er401kCap_base, er401kCap_catch)), MAX( 0, MIN($B14, IF($A14>=specialCatchStartAge, IF($A14<=specialCatchEndAge, total401kCap_60to63, total401kCap_50to59), IF($A14>=catchAge, total401kCap_50to59, total401kCap_u50) ) ) - $C14 ) ), 2) -> 43500 | E14: =MAX(0, $B14 - $C14) -> 530633.29 | F14: =IFERROR( IF($A14 < MarriageAge, SUMPRODUCT( ($E14>FedLower_Single) * ((IF($E14>FedUpper_Single, FedUpper_Single, $E14))-FedLower_Single) * FedRate_Single ), SUMPRODUCT( ($E14>FedLower_Married) * ((IF($E14>FedUpper_Married, FedUpper_Married, $E14))-FedLower_Married) * FedRate_Married ) ), 0) -> 123339.14 | G14: =ROUND(gaEff*$E14, 2) -> 27539.87 | H14: =IF($B14=0,0, ROUND( ssRate*MIN($B14, ssBase) + medRate*$B14 + addlMedRate*MAX(0, $B14 - addlMedThresh), 2)) -> 22628.83 | I14: =IF($B14=0,0, ROUND($B14 - $C14 - $F14 - $G14 - $H14, 2)) -> 357125.45 | J14: =ROUND( MIN(rothIRA, IF($A14<catchAge, rothCap_base, rothCap_catch)), 2) -> 7000 | K14: =ROUND(($I14-$J14-$X14)*allocETF, 2) + IFERROR($P14, 0) -> 70025.09 | L14: =ROUND( ($I14-$J14-$X14)*allocRE , 2) -> 52518.82 | M14: =LET( cap_ratio, IFERROR(savings_cap_ratio, 0.75), cap_amt, cap_ratio * $W14, start_sav, IFERROR(Balances!$S14, 0), base, ROUND(($I14-$J14-$X14)*allocSav, 2), IF(start_sav >= cap_amt, 0, base) ) -> 17506.27 | N14: =IF($A14<=capAge, MIN( ROUND( ($I14-$J14-$X14)*(1-allocETF-allocRE-allocSav), 2), capBase * (1 + inflation) ^ ($A14 - startAge) ), ROUND( ($I14-$J14-$X14)*(1-allocETF-allocRE-allocSav), 2) ) -> 210075.27 | O14: =LET( cap_ratio, IFERROR(savings_cap_ratio, 0.75), cap_amt, cap_ratio * $W14, start_sav, IFERROR(Balances!$S14, 0), base, ROUND(($I14-$J14-$X14)*allocSav, 2), IF(start_sav >= cap_amt, base, 0) ) -> 0 | P14: =IFERROR($O14 * IFERROR(surplus_to_ETF, 0.4), 0) -> 0 | Q14: =IFERROR($O14 * IFERROR(surplus_to_RE, 0.6), 0) -> 0 | R14: =IF($A14<=capAge, MAX( 0, ROUND( ($I14-$J14-$X14)*(1-allocETF-allocRE-allocSav) - capBase * (1 + inflation) ^ ($A14 - startAge), 2) ), 0 ) -> 0 | S14: =IF(R14>0, R14*lifeExcessToETF, 0) -> 0 | T14: =IF(R14>0, R14*lifeExcessToLoan, 0) -> 0 | U14: =ROUND( MIN( X14 + IFERROR(T14,0), AB14 + Y14 ), 2 ) -> 0 | V14: {=LET( age,$A14, ti_prev,N($E13), gross,SUMIF('RE Amortization'!$E:$E,$A14,'RE Amortization'!$K:$K), fed_single,IFERROR(LOOKUP(ti_prev,N(Assumptions!$D$3:$D$9),N(Assumptions!$F$3:$F$9)),INDEX(N(Assumptions!$F$3:$F$9),1)), fed_married,IFERROR(LOOKUP(ti_prev,N(Assumptions!$D$13:$D$19),N(Assumptions!$F$13:$F$19)),INDEX(N(Assumptions!$F$13:$F$19),1)), fed_rate,IF(age<MarriageAge,fed_single,fed_married), ROUND(gross*(1-fed_rate-gaEff),2) )} -> 8421.31 | W14: =IFERROR(N14 + V14, N14) -> 218496.58 | X14: {=IF( AB14<=0,0, IF( A14<loanStartAge,0, MIN( AB14 + ROUND(AB14*loanRate,2), IF(A14=loanStartAge, cfiPayPct * I14, -PMT(loanRate,loanTerm,INDEX($AB:$AB,MATCH(loanStartAge,$A:$A,0))) ) ) ) )} -> 0 | Y14: =IF(AB14<=0,0,ROUND(AB14*loanRate,2)) -> 0 | Z14: =IF(OR(AB14<=0,U14<=0),0,ROUND(MIN(AB14+Y14,U14)-Y14,2)) -> 0 | AA14: =MAX(0,ROUND(AB14 + Y14 - U14,2)) -> 0 | AB14: =IF(A14=18, loanStartBal, OFFSET(AA14,-1,0)) -> 0
A15: 31 | B15: =IFERROR(__xludf.DUMMYFUNCTION("IFERROR( INDEX( FILTER('Pilot Pay'!R:R, VALUE('Pilot Pay'!K:K)=VALUE($A15)) , 1 ), 0 ) "),574098.33) -> 574098.33 | C15: =ROUND( MIN($B15*emp401kPct, IF($A15<catchAge, emp401kCap, emp401kCap_catch)), 2) -> 24500 | D15: =ROUND( MIN( MIN($B15*er401kPct, IF($A15<catchAge, er401kCap_base, er401kCap_catch)), MAX( 0, MIN($B15, IF($A15>=specialCatchStartAge, IF($A15<=specialCatchEndAge, total401kCap_60to63, total401kCap_50to59), IF($A15>=catchAge, total401kCap_50to59, total401kCap_u50) ) ) - $C15 ) ), 2) -> 43500 | E15: =MAX(0, $B15 - $C15) -> 549598.33 | F15: =IFERROR( IF($A15 < MarriageAge, SUMPRODUCT( ($E15>FedLower_Single) * ((IF($E15>FedUpper_Single, FedUpper_Single, $E15))-FedLower_Single) * FedRate_Single ), SUMPRODUCT( ($E15>FedLower_Married) * ((IF($E15>FedUpper_Married, FedUpper_Married, $E15))-FedLower_Married) * FedRate_Married ) ), 0) -> 129976.91 | G15: =ROUND(gaEff*$E15, 2) -> 28524.15 | H15: =IF($B15=0,0, ROUND( ssRate*MIN($B15, ssBase) + medRate*$B15 + addlMedRate*MAX(0, $B15 - addlMedThresh), 2)) -> 23074.51 | I15: =IF($B15=0,0, ROUND($B15 - $C15 - $F15 - $G15 - $H15, 2)) -> 368022.76 | J15: =ROUND( MIN(rothIRA, IF($A15<catchAge, rothCap_base, rothCap_catch)), 2) -> 7000 | K15: =ROUND(($I15-$J15-$X15)*allocETF, 2) + IFERROR($P15, 0) -> 72204.55 | L15: =ROUND( ($I15-$J15-$X15)*allocRE , 2) -> 54153.41 | M15: =LET( cap_ratio, IFERROR(savings_cap_ratio, 0.75), cap_amt, cap_ratio * $W15, start_sav, IFERROR(Balances!$S15, 0), base, ROUND(($I15-$J15-$X15)*allocSav, 2), IF(start_sav >= cap_amt, 0, base) ) -> 18051.14 | N15: =IF($A15<=capAge, MIN( ROUND( ($I15-$J15-$X15)*(1-allocETF-allocRE-allocSav), 2), capBase * (1 + inflation) ^ ($A15 - startAge) ), ROUND( ($I15-$J15-$X15)*(1-allocETF-allocRE-allocSav), 2) ) -> 216613.66 | O15: =LET( cap_ratio, IFERROR(savings_cap_ratio, 0.75), cap_amt, cap_ratio * $W15, start_sav, IFERROR(Balances!$S15, 0), base, ROUND(($I15-$J15-$X15)*allocSav, 2), IF(start_sav >= cap_amt, base, 0) ) -> 0 | P15: =IFERROR($O15 * IFERROR(surplus_to_ETF, 0.4), 0) -> 0 | Q15: =IFERROR($O15 * IFERROR(surplus_to_RE, 0.6), 0) -> 0 | R15: =IF($A15<=capAge, MAX( 0, ROUND( ($I15-$J15-$X15)*(1-allocETF-allocRE-allocSav) - capBase * (1 + inflation) ^ ($A15 - startAge), 2) ), 0 ) -> 0 | S15: =IF(R15>0, R15*lifeExcessToETF, 0) -> 0 | T15: =IF(R15>0, R15*lifeExcessToLoan, 0) -> 0 | U15: =ROUND( MIN( X15 + IFERROR(T15,0), AB15 + Y15 ), 2 ) -> 0 | V15: {=LET( age,$A15, ti_prev,N($E14), gross,SUMIF('RE Amortization'!$E:$E,$A15,'RE Amortization'!$K:$K), fed_single,IFERROR(LOOKUP(ti_prev,N(Assumptions!$D$3:$D$9),N(Assumptions!$F$3:$F$9)),INDEX(N(Assumptions!$F$3:$F$9),1)), fed_married,IFERROR(LOOKUP(ti_prev,N(Assumptions!$D$13:$D$19),N(Assumptions!$F$13:$F$19)),INDEX(N(Assumptions!$F$13:$F$19),1)), fed_rate,IF(age<MarriageAge,fed_single,fed_married), ROUND(gross*(1-fed_rate-gaEff),2) )} -> 7469.89 | W15: =IFERROR(N15 + V15, N15) -> 224083.55 | X15: {=IF( AB15<=0,0, IF( A15<loanStartAge,0, MIN( AB15 + ROUND(AB15*loanRate,2), IF(A15=loanStartAge, cfiPayPct * I15, -PMT(loanRate,loanTerm,INDEX($AB:$AB,MATCH(loanStartAge,$A:$A,0))) ) ) ) )} -> 0 | Y15: =IF(AB15<=0,0,ROUND(AB15*loanRate,2)) -> 0 | Z15: =IF(OR(AB15<=0,U15<=0),0,ROUND(MIN(AB15+Y15,U15)-Y15,2)) -> 0 | AA15: =MAX(0,ROUND(AB15 + Y15 - U15,2)) -> 0 | AB15: =IF(A15=18, loanStartBal, OFFSET(AA15,-1,0)) -> 0
A16: 32 | B16: =IFERROR(__xludf.DUMMYFUNCTION("IFERROR( INDEX( FILTER('Pilot Pay'!R:R, VALUE('Pilot Pay'!K:K)=VALUE($A16)) , 1 ), 0 ) "),578544.43) -> 578544.43 | C16: =ROUND( MIN($B16*emp401kPct, IF($A16<catchAge, emp401kCap, emp401kCap_catch)), 2) -> 24500 | D16: =ROUND( MIN( MIN($B16*er401kPct, IF($A16<catchAge, er401kCap_base, er401kCap_catch)), MAX( 0, MIN($B16, IF($A16>=specialCatchStartAge, IF($A16<=specialCatchEndAge, total401kCap_60to63, total401kCap_50to59), IF($A16>=catchAge, total401kCap_50to59, total401kCap_u50) ) ) - $C16 ) ), 2) -> 43500 | E16: =MAX(0, $B16 - $C16) -> 554044.43 | F16: =IFERROR( IF($A16 < MarriageAge, SUMPRODUCT( ($E16>FedLower_Single) * ((IF($E16>FedUpper_Single, FedUpper_Single, $E16))-FedLower_Single) * FedRate_Single ), SUMPRODUCT( ($E16>FedLower_Married) * ((IF($E16>FedUpper_Married, FedUpper_Married, $E16))-FedLower_Married) * FedRate_Married ) ), 0) -> 131533.04 | G16: =ROUND(gaEff*$E16, 2) -> 28754.91 | H16: =IF($B16=0,0, ROUND( ssRate*MIN($B16, ssBase) + medRate*$B16 + addlMedRate*MAX(0, $B16 - addlMedThresh), 2)) -> 23178.99 | I16: =IF($B16=0,0, ROUND($B16 - $C16 - $F16 - $G16 - $H16, 2)) -> 370577.49 | J16: =ROUND( MIN(rothIRA, IF($A16<catchAge, rothCap_base, rothCap_catch)), 2) -> 7000 | K16: =ROUND(($I16-$J16-$X16)*allocETF, 2) + IFERROR($P16, 0) -> 72715.5 | L16: =ROUND( ($I16-$J16-$X16)*allocRE , 2) -> 54536.62 | M16: =LET( cap_ratio, IFERROR(savings_cap_ratio, 0.75), cap_amt, cap_ratio * $W16, start_sav, IFERROR(Balances!$S16, 0), base, ROUND(($I16-$J16-$X16)*allocSav, 2), IF(start_sav >= cap_amt, 0, base) ) -> 18178.87 | N16: =IF($A16<=capAge, MIN( ROUND( ($I16-$J16-$X16)*(1-allocETF-allocRE-allocSav), 2), capBase * (1 + inflation) ^ ($A16 - startAge) ), ROUND( ($I16-$J16-$X16)*(1-allocETF-allocRE-allocSav), 2) ) -> 218146.49 | O16: =LET( cap_ratio, IFERROR(savings_cap_ratio, 0.75), cap_amt, cap_ratio * $W16, start_sav, IFERROR(Balances!$S16, 0), base, ROUND(($I16-$J16-$X16)*allocSav, 2), IF(start_sav >= cap_amt, base, 0) ) -> 0 | P16: =IFERROR($O16 * IFERROR(surplus_to_ETF, 0.4), 0) -> 0 | Q16: =IFERROR($O16 * IFERROR(surplus_to_RE, 0.6), 0) -> 0 | R16: =IF($A16<=capAge, MAX( 0, ROUND( ($I16-$J16-$X16)*(1-allocETF-allocRE-allocSav) - capBase * (1 + inflation) ^ ($A16 - startAge), 2) ), 0 ) -> 0 | S16: =IF(R16>0, R16*lifeExcessToETF, 0) -> 0 | T16: =IF(R16>0, R16*lifeExcessToLoan, 0) -> 0 | U16: =ROUND( MIN( X16 + IFERROR(T16,0), AB16 + Y16 ), 2 ) -> 0 | V16: {=LET( age,$A16, ti_prev,N($E15), gross,SUMIF('RE Amortization'!$E:$E,$A16,'RE Amortization'!$K:$K), fed_single,IFERROR(LOOKUP(ti_prev,N(Assumptions!$D$3:$D$9),N(Assumptions!$F$3:$F$9)),INDEX(N(Assumptions!$F$3:$F$9),1)), fed_married,IFERROR(LOOKUP(ti_prev,N(Assumptions!$D$13:$D$19),N(Assumptions!$F$13:$F$19)),INDEX(N(Assumptions!$F$13:$F$19),1)), fed_rate,IF(age<MarriageAge,fed_single,fed_married), ROUND(gross*(1-fed_rate-gaEff),2) )} -> 7113.1 | W16: =IFERROR(N16 + V16, N16) -> 225259.59 | X16: {=IF( AB16<=0,0, IF( A16<loanStartAge,0, MIN( AB16 + ROUND(AB16*loanRate,2), IF(A16=loanStartAge, cfiPayPct * I16, -PMT(loanRate,loanTerm,INDEX($AB:$AB,MATCH(loanStartAge,$A:$A,0))) ) ) ) )} -> 0 | Y16: =IF(AB16<=0,0,ROUND(AB16*loanRate,2)) -> 0 | Z16: =IF(OR(AB16<=0,U16<=0),0,ROUND(MIN(AB16+Y16,U16)-Y16,2)) -> 0 | AA16: =MAX(0,ROUND(AB16 + Y16 - U16,2)) -> 0 | AB16: =IF(A16=18, loanStartBal, OFFSET(AA16,-1,0)) -> 0
A17: 33 | B17: =IFERROR(__xludf.DUMMYFUNCTION("IFERROR( INDEX( FILTER('Pilot Pay'!R:R, VALUE('Pilot Pay'!K:K)=VALUE($A17)) , 1 ), 0 ) "),597817.84) -> 597817.84 | C17: =ROUND( MIN($B17*emp401kPct, IF($A17<catchAge, emp401kCap, emp401kCap_catch)), 2) -> 24500 | D17: =ROUND( MIN( MIN($B17*er401kPct, IF($A17<catchAge, er401kCap_base, er401kCap_catch)), MAX( 0, MIN($B17, IF($A17>=specialCatchStartAge, IF($A17<=specialCatchEndAge, total401kCap_60to63, total401kCap_50to59), IF($A17>=catchAge, total401kCap_50to59, total401kCap_u50) ) ) - $C17 ) ), 2) -> 43500 | E17: =MAX(0, $B17 - $C17) -> 573317.84 | F17: =IFERROR( IF($A17 < MarriageAge, SUMPRODUCT( ($E17>FedLower_Single) * ((IF($E17>FedUpper_Single, FedUpper_Single, $E17))-FedLower_Single) * FedRate_Single ), SUMPRODUCT( ($E17>FedLower_Married) * ((IF($E17>FedUpper_Married, FedUpper_Married, $E17))-FedLower_Married) * FedRate_Married ) ), 0) -> 138278.73 | G17: =ROUND(gaEff*$E17, 2) -> 29755.2 | H17: =IF($B17=0,0, ROUND( ssRate*MIN($B17, ssBase) + medRate*$B17 + addlMedRate*MAX(0, $B17 - addlMedThresh), 2)) -> 23631.92 | I17: =IF($B17=0,0, ROUND($B17 - $C17 - $F17 - $G17 - $H17, 2)) -> 381651.99 | J17: =ROUND( MIN(rothIRA, IF($A17<catchAge, rothCap_base, rothCap_catch)), 2) -> 7000 | K17: =ROUND(($I17-$J17-$X17)*allocETF, 2) + IFERROR($P17, 0) -> 74930.4 | L17: =ROUND( ($I17-$J17-$X17)*allocRE , 2) -> 56197.8 | M17: =LET( cap_ratio, IFERROR(savings_cap_ratio, 0.75), cap_amt, cap_ratio * $W17, start_sav, IFERROR(Balances!$S17, 0), base, ROUND(($I17-$J17-$X17)*allocSav, 2), IF(start_sav >= cap_amt, 0, base) ) -> 18732.6 | N17: =IF($A17<=capAge, MIN( ROUND( ($I17-$J17-$X17)*(1-allocETF-allocRE-allocSav), 2), capBase * (1 + inflation) ^ ($A17 - startAge) ), ROUND( ($I17-$J17-$X17)*(1-allocETF-allocRE-allocSav), 2) ) -> 224791.19 | O17: =LET( cap_ratio, IFERROR(savings_cap_ratio, 0.75), cap_amt, cap_ratio * $W17, start_sav, IFERROR(Balances!$S17, 0), base, ROUND(($I17-$J17-$X17)*allocSav, 2), IF(start_sav >= cap_amt, base, 0) ) -> 0 | P17: =IFERROR($O17 * IFERROR(surplus_to_ETF, 0.4), 0) -> 0 | Q17: =IFERROR($O17 * IFERROR(surplus_to_RE, 0.6), 0) -> 0 | R17: =IF($A17<=capAge, MAX( 0, ROUND( ($I17-$J17-$X17)*(1-allocETF-allocRE-allocSav) - capBase * (1 + inflation) ^ ($A17 - startAge), 2) ), 0 ) -> 0 | S17: =IF(R17>0, R17*lifeExcessToETF, 0) -> 0 | T17: =IF(R17>0, R17*lifeExcessToLoan, 0) -> 0 | U17: =ROUND( MIN( X17 + IFERROR(T17,0), AB17 + Y17 ), 2 ) -> 0 | V17: {=LET( age,$A17, ti_prev,N($E16), gross,SUMIF('RE Amortization'!$E:$E,$A17,'RE Amortization'!$K:$K), fed_single,IFERROR(LOOKUP(ti_prev,N(Assumptions!$D$3:$D$9),N(Assumptions!$F$3:$F$9)),INDEX(N(Assumptions!$F$3:$F$9),1)), fed_married,IFERROR(LOOKUP(ti_prev,N(Assumptions!$D$13:$D$19),N(Assumptions!$F$13:$F$19)),INDEX(N(Assumptions!$F$13:$F$19),1)), fed_rate,IF(age<MarriageAge,fed_single,fed_married), ROUND(gross*(1-fed_rate-gaEff),2) )} -> 13436.77 | W17: =IFERROR(N17 + V17, N17) -> 238227.96 | X17: {=IF( AB17<=0,0, IF( A17<loanStartAge,0, MIN( AB17 + ROUND(AB17*loanRate,2), IF(A17=loanStartAge, cfiPayPct * I17, -PMT(loanRate,loanTerm,INDEX($AB:$AB,MATCH(loanStartAge,$A:$A,0))) ) ) ) )} -> 0 | Y17: =IF(AB17<=0,0,ROUND(AB17*loanRate,2)) -> 0 | Z17: =IF(OR(AB17<=0,U17<=0),0,ROUND(MIN(AB17+Y17,U17)-Y17,2)) -> 0 | AA17: =MAX(0,ROUND(AB17 + Y17 - U17,2)) -> 0 | AB17: =IF(A17=18, loanStartBal, OFFSET(AA17,-1,0)) -> 0
A18: 34 | B18: =IFERROR(__xludf.DUMMYFUNCTION("IFERROR( INDEX( FILTER('Pilot Pay'!R:R, VALUE('Pilot Pay'!K:K)=VALUE($A18)) , 1 ), 0 ) "),617789.19) -> 617789.19 | C18: =ROUND( MIN($B18*emp401kPct, IF($A18<catchAge, emp401kCap, emp401kCap_catch)), 2) -> 24500 | D18: =ROUND( MIN( MIN($B18*er401kPct, IF($A18<catchAge, er401kCap_base, er401kCap_catch)), MAX( 0, MIN($B18, IF($A18>=specialCatchStartAge, IF($A18<=specialCatchEndAge, total401kCap_60to63, total401kCap_50to59), IF($A18>=catchAge, total401kCap_50to59, total401kCap_u50) ) ) - $C18 ) ), 2) -> 43500 | E18: =MAX(0, $B18 - $C18) -> 593289.19 | F18: =IFERROR( IF($A18 < MarriageAge, SUMPRODUCT( ($E18>FedLower_Single) * ((IF($E18>FedUpper_Single, FedUpper_Single, $E18))-FedLower_Single) * FedRate_Single ), SUMPRODUCT( ($E18>FedLower_Married) * ((IF($E18>FedUpper_Married, FedUpper_Married, $E18))-FedLower_Married) * FedRate_Married ) ), 0) -> 145268.71 | G18: =ROUND(gaEff*$E18, 2) -> 30791.71 | H18: =IF($B18=0,0, ROUND( ssRate*MIN($B18, ssBase) + medRate*$B18 + addlMedRate*MAX(0, $B18 - addlMedThresh), 2)) -> 24101.25 | I18: =IF($B18=0,0, ROUND($B18 - $C18 - $F18 - $G18 - $H18, 2)) -> 393127.52 | J18: =ROUND( MIN(rothIRA, IF($A18<catchAge, rothCap_base, rothCap_catch)), 2) -> 7000 | K18: =ROUND(($I18-$J18-$X18)*allocETF, 2) + IFERROR($P18, 0) -> 77225.5 | L18: =ROUND( ($I18-$J18-$X18)*allocRE , 2) -> 57919.13 | M18: =LET( cap_ratio, IFERROR(savings_cap_ratio, 0.75), cap_amt, cap_ratio * $W18, start_sav, IFERROR(Balances!$S18, 0), base, ROUND(($I18-$J18-$X18)*allocSav, 2), IF(start_sav >= cap_amt, 0, base) ) -> 19306.38 | N18: =IF($A18<=capAge, MIN( ROUND( ($I18-$J18-$X18)*(1-allocETF-allocRE-allocSav), 2), capBase * (1 + inflation) ^ ($A18 - startAge) ), ROUND( ($I18-$J18-$X18)*(1-allocETF-allocRE-allocSav), 2) ) -> 231676.51 | O18: =LET( cap_ratio, IFERROR(savings_cap_ratio, 0.75), cap_amt, cap_ratio * $W18, start_sav, IFERROR(Balances!$S18, 0), base, ROUND(($I18-$J18-$X18)*allocSav, 2), IF(start_sav >= cap_amt, base, 0) ) -> 0 | P18: =IFERROR($O18 * IFERROR(surplus_to_ETF, 0.4), 0) -> 0 | Q18: =IFERROR($O18 * IFERROR(surplus_to_RE, 0.6), 0) -> 0 | R18: =IF($A18<=capAge, MAX( 0, ROUND( ($I18-$J18-$X18)*(1-allocETF-allocRE-allocSav) - capBase * (1 + inflation) ^ ($A18 - startAge), 2) ), 0 ) -> 0 | S18: =IF(R18>0, R18*lifeExcessToETF, 0) -> 0 | T18: =IF(R18>0, R18*lifeExcessToLoan, 0) -> 0 | U18: =ROUND( MIN( X18 + IFERROR(T18,0), AB18 + Y18 ), 2 ) -> 0 | V18: {=LET( age,$A18, ti_prev,N($E17), gross,SUMIF('RE Amortization'!$E:$E,$A18,'RE Amortization'!$K:$K), fed_single,IFERROR(LOOKUP(ti_prev,N(Assumptions!$D$3:$D$9),N(Assumptions!$F$3:$F$9)),INDEX(N(Assumptions!$F$3:$F$9),1)), fed_married,IFERROR(LOOKUP(ti_prev,N(Assumptions!$D$13:$D$19),N(Assumptions!$F$13:$F$19)),INDEX(N(Assumptions!$F$13:$F$19),1)), fed_rate,IF(age<MarriageAge,fed_single,fed_married), ROUND(gross*(1-fed_rate-gaEff),2) )} -> 17496.77 | W18: =IFERROR(N18 + V18, N18) -> 249173.28 | X18: {=IF( AB18<=0,0, IF( A18<loanStartAge,0, MIN( AB18 + ROUND(AB18*loanRate,2), IF(A18=loanStartAge, cfiPayPct * I18, -PMT(loanRate,loanTerm,INDEX($AB:$AB,MATCH(loanStartAge,$A:$A,0))) ) ) ) )} -> 0 | Y18: =IF(AB18<=0,0,ROUND(AB18*loanRate,2)) -> 0 | Z18: =IF(OR(AB18<=0,U18<=0),0,ROUND(MIN(AB18+Y18,U18)-Y18,2)) -> 0 | AA18: =MAX(0,ROUND(AB18 + Y18 - U18,2)) -> 0 | AB18: =IF(A18=18, loanStartBal, OFFSET(AA18,-1,0)) -> 0
